Workbook

Sheet CAPA
A1: MODELO DE VALUE AT RISK – IBOVESPA
A2: Risco de Mercado | Tesouraria & Gestão de Ativos
B4: Versão do Modelo: | D4: 2.1
B5: Data de Referência: | D5: 03/06/2026
B6: Área Responsável: | D6: Risco de Mercado – Tesouraria
B7: Elaborado por: | D7: Equipe de Modelagem Quantitativa
B8: Revisado por: | D8: Gerência de Risco de Mercado
B9: Aprovado por: | D9: Diretoria de Risco
B10: Próxima Revisão: | D10: 03/12/2026
B11: Status: | D11: ATIVO
B13: AVISO LEGAL: Este modelo é de uso exclusivo interno. Os resultados apresentados são estimativas estatísticas baseadas em dados históricos e não constituem garantia de resultados futuros. O uso inadequado deste modelo para fins regulatórios sem validação prévia pela área de Risco é vedado. Modelos de VaR possuem limitações inerentes e devem ser complementados por testes de estresse e análises de sensibilidade.
B18: ÍNDICE DE ABAS
B19: CAPA | D19: Identificação e controle do modelo
B20: PARÂMETROS | D20: Parâmetros globais e premissas do modelo
B21: RETORNOS_HIST | D21: Série histórica de preços e retornos do Ibovespa
B22: VaR_HISTÓRICO | D22: VaR pelo método de simulação histórica
B23: VaR_PARAMÉTRICO | D23: VaR delta-normal (média e desvio padrão)
B24: EWMA_VOL | D24: Volatilidade EWMA – RiskMetrics (λ=0,94)
B25: BACKTESTING | D25: Backtesting e semáforo de Basileia
B26: STRESS_TEST | D26: Cenários de estresse históricos e hipotéticos
B27: MONTE_CARLO | D27: Simulação Monte Carlo (1 000 cenários)
B28: RESUMO_EXEC | D28: Dashboard executivo – consolidação dos VaRs

Sheet PARÂMETROS
A1: PARÂMETROS DO MODELO DE VaR
A2: PARÂMETRO | B2: VALOR | C2: UNIDADE | F2: OBSERVAÇÃO
A3: 1. NÍVEL DE CONFIANÇA
A4: Nível de Confiança Principal | B4: 0.99 | F4: conf_99
A5: Nível de Confiança Secundário | B5: 0.95 | F5: conf_95
A6: Nível de Confiança Expected Shortfall | B6: 0.975 | F6: CVaR interno
A7: 2. HORIZONTE TEMPORAL
A8: Horizonte Principal (dias úteis) | B8: 1 | C8: dia(s) | F8: horiz_1d
A9: Horizonte Regulatório | B9: 10 | C9: dias | F9: horiz_10d
A10: Dias Úteis por Ano | B10: 252 | C10: dias | F10: Convenção mercado brasileiro
A11: 3. JANELA HISTÓRICA
A12: Janela Curta (dias úteis) | B12: 252 | C12: dias | F12: jan_curta
A13: Janela Longa (dias úteis) | B13: 500 | C13: dias | F13: ~2 anos – backtesting regulatório
A14: Janela de Backtesting | B14: 250 | C14: dias | F14: Basileia – 250 dias úteis
A15: 4. METODOLOGIAS
A16: Método 1 | B16: Histórico | F16: Distribuição empírica dos retornos
A17: Método 2 | B17: Paramétrico | F17: Delta-Normal – assume distribuição normal
A18: Método 3 | B18: Monte Carlo | F18: Simulação com 1 000 cenários
A19: Método 4 | B19: EWMA | F19: RiskMetrics – volatilidade com memória exponencial
A20: 5. PARÂMETROS EWMA
A21: Fator de Decaimento (λ) | B21: 0.94 | F21: lambda_ewma
A22: Half-life (dias) | B22: 11 | C22: dias | F22: ln(0.5)/ln(λ) ≈ 11 dias para λ=0,94
A23: 6. POSIÇÃO / NOCIONAL
A24: Valor Nocional da Posição | B24: 10000000 | C24: BRL | F24: nocional
A25: Moeda | B25: BRL | F25: Real Brasileiro
A26: Índice de Referência | B26: Ibovespa | F26: B3 – Bolsa Brasil Balcão
A27: 7. LIMITES REGULATÓRIOS (BACKTESTING)
A28: Zona Verde – máx. exceções | B28: 4 | C28: exceções/250d | F28: Basileia – fator multiplicador = 3
A29: Zona Amarela – máx. exceções | B29: 9 | C29: exceções/250d | F29: Basileia – fator multiplicador = 3+
A30: Zona Vermelha – mín. exceções | B30: 10 | C30: exceções/250d | F30: Basileia – modelo rejeitado

Sheet RETORNOS_HIST
A1: SÉRIE HISTÓRICA DE RETORNOS – IBOVESPA (Jan/2022 – Dez/2023)
A2: DATA | B2: IBOVESPA (pts) | C2: RETORNO LOG | D2: RETORNO (%) | E2: RET² (EWMA input) | F2: OBSERVAÇÃO
A3: 44564 | B3: 104000 | C3: — | D3: — | E3: —
A4: 44565 | B4: 103800.01 | C4: =LN(B4/B3) | D4: =(B4/B3)-1 | E4: =C4^2
A5: 44566 | B5: 103677 | C5: =LN(B5/B4) | D5: =(B5/B4)-1 | E5: =C5^2
A6: 44567 | B6: 104569.73 | C6: =LN(B6/B5) | D6: =(B6/B5)-1 | E6: =C6^2
A7: 44568 | B7: 104425.41 | C7: =LN(B7/B6) | D7: =(B7/B6)-1 | E7: =C7^2
A8: 44571 | B8: 102581.21 | C8: =LN(B8/B7) | D8: =(B8/B7)-1 | E8: =C8^2
A9: 44572 | B9: 103006.55 | C9: =LN(B9/B8) | D9: =(B9/B8)-1 | E9: =C9^2
A10: 44573 | B10: 102692.03 | C10: =LN(B10/B9) | D10: =(B10/B9)-1 | E10: =C10^2
A11: 44574 | B11: 102440.38 | C11: =LN(B11/B10) | D11: =(B11/B10)-1 | E11: =C11^2
A12: 44575 | B12: 102598.32 | C12: =LN(B12/B11) | D12: =(B12/B11)-1 | E12: =C12^2
A13: 44578 | B13: 102900.15 | C13: =LN(B13/B12) | D13: =(B13/B12)-1 | E13: =C13^2
A14: 44579 | B14: 104362.64 | C14: =LN(B14/B13) | D14: =(B14/B13)-1 | E14: =C14^2
A15: 44580 | B15: 105204.01 | C15: =LN(B15/B14) | D15: =(B15/B14)-1 | E15: =C15^2
... A22: 44589 | B22: 105125.47 | C22: =LN(B22/B21) | D22: =(B22/B21)-1 | E22: =C22^2
A23: 44592 | B23: 100198.64 | C23: =LN(B23/B22) | D23: =(B23/B22)-1 | E23: =C23^2 | F23: Choque de volatilidade
A24: 44593 | B24: 100855.21 | C24: =LN(B24/B23) | D24: =(B24/B23)-1 | E24: =C24^2
A25: 44594 | B25: 99126.16 | C25: =LN(B25/B24) | D25: =(B25/B24)-1 | E25: =C25^2
A26: 44595 | B26: 98770.21 | C26: =LN(B26/B25) | D26: =(B26/B25)-1 | E26: =C26^2
A27: 44596 | B27: 99368.03 | C27: =LN(B27/B26) | D27: =(B27/B26)-1 | E27: =C27^2
A28: 44599 | B28: 103319.94 | C28: =LN(B28/B27) | D28: =(B28/B27)-1 | E28: =C28^2 | F28: Recuperação forte
A29: 44600 | B29: 104424.18 | C29: =LN(B29/B28) | D29: =(B29/B28)-1 | E29: =C29^2
A30: 44601 | B30: 104138.7 | C30: =LN(B30/B29) | D30: =(B30/B29)-1 | E30: =C30^2
A31: 44602 | B31: 104626.08 | C31: =LN(B31/B30) | D31: =(B31/B30)-1 | E31: =C31^2
A32: 44603 | B32: 104953.92 | C32: =LN(B32/B31) | D32: =(B32/B31)-1 | E32: =C32^2
A33: 44606 | B33: 105959.75 | C33: =LN(B33/B32) | D33: =(B33/B32)-1 | E33: =C33^2
A34: 44607 | B34: 104569.37 | C34: =LN(B34/B33) | D34: =(B34/B33)-1 | E34: =C34^2
A35: 44608 | B35: 105300.66 | C35: =LN(B35/B34) | D35: =(B35/B34)-1 | E35: =C35^2
A36: 44609 | B36: 103419.7 | C36: =LN(B36/B35) | D36: =(B36/B35)-1 | E36: =C36^2
A37: 44610 | B37: 100233.87 | C37: =LN(B37/B36) | D37: =(B37/B36)-1 | E37: =C37^2
A38: 44613 | B38: 99521.48 | C38: =LN(B38/B37) | D38: =(B38/B37)-1 | E38: =C38^2
A39: 44614 | B39: 98448.52 | C39: =LN(B39/B38) | D39: =(B39/B38)-1 | E39: =C39^2
A40: 44615 | B40: 99503.81 | C40: =LN(B40/B39) | D40: =(B40/B39)-1 | E40: =C40^2
... A62: 44645 | B62: 103495.63 | C62: =LN(B62/B61) | D62: =(B62/B61)-1 | E62: =C62^2
A63: 44648 | B63: 99338.12 | C63: =LN(B63/B62) | D63: =(B63/B62)-1 | E63: =C63^2 | F63: Pressão vendedora
A64: 44649 | B64: 99957.76 | C64: =LN(B64/B63) | D64: =(B64/B63)-1 | E64: =C64^2
A65: 44650 | B65: 100980.51 | C65: =LN(B65/B64) | D65: =(B65/B64)-1 | E65: =C65^2
A66: 44651 | B66: 102739.19 | C66: =LN(B66/B65) | D66: =(B66/B65)-1 | E66: =C66^2
A67: 44652 | B67: 102638.73 | C67: =LN(B67/B66) | D67: =(B67/B66)-1 | E67: =C67^2
...

Sheet VaR_HISTÓRICO
A1: VaR – MÉTODO DE SIMULAÇÃO HISTÓRICA
A2: Metodologia: Utiliza os retornos logarítmicos históricos observados, ordenados do menor ao maior. O VaR é estimado como o percentil correspondente ao nível de confiança (ex.: 1% dos piores retornos para VaR 99%). Não assume distribuição paramétrica dos retornos. | Fonte: RETORNOS_HIST
A5: PARÂMETROS UTILIZADOS
A6: Nível de Confiança 99% | B6: =PARÂMETROS!B4
A7: Nível de Confiança 95% | B7: =PARÂMETROS!B5
A8: Janela Histórica (dias) | B8: =PARÂMETROS!B12
A9: Nocional (R$) | B9: =PARÂMETROS!B24
A10: Horizonte 1d | B10: =PARÂMETROS!B8
A11: Horizonte 10d (escalonado) | B11: =PARÂMETROS!B9
A13: RESULTADOS – VaR HISTÓRICO
A14: MÉTRICA | B14: NÍVEL CONF. | C14: HORIZONTE | D14: VaR (%) | E14: VaR (R$) | F14: ES/CVaR (%) | G14: ES/CVaR (R$)
A15: VaR Histórico | B15: 99% | C15: 1 dia | D15: =ABS(PERCENTILE(RETORNOS_HIST!C4:C522,1-PARÂMETROS!B4)) | E15: =D15*PARÂMETROS!B24 | F15: =AVERAGEIF(RETORNOS_HIST!C4:C522,"<"&PERCENTILE(RETORNOS_HIST!C4:C522,1-PARÂMETROS!B4))*-1 | G15: =F15*PARÂMETROS!B24
A16: VaR Histórico | B16: 95% | C16: 1 dia | D16: =ABS(PERCENTILE(RETORNOS_HIST!C4:C522,1-PARÂMETROS!B5)) | E16: =D16*PARÂMETROS!B24 | F16: =AVERAGEIF(RETORNOS_HIST!C4:C522,"<"&PERCENTILE(RETORNOS_HIST!C4:C522,1-PARÂMETROS!B5))*-1 | G16: =F16*PARÂMETROS!B24
A17: VaR Hist. √10 | B17: 99% | C17: 10 dias | D17: =ABS(PERCENTILE(RETORNOS_HIST!C4:C522,1-PARÂMETROS!B4))*SQRT(PARÂMETROS!B9) | E17: =D17*PARÂMETROS!B24 | F17: =AVERAGEIF(RETORNOS_HIST!C4:C522,"<"&PERCENTILE(RETORNOS_HIST!C4:C522,1-PARÂMETROS!B4))*-1*SQRT(PARÂMETROS!B9) | G17: =F17*PARÂMETROS!B24
A18: VaR Hist. √10 | B18: 95% | C18: 10 dias | D18: =ABS(PERCENTILE(RETORNOS_HIST!C4:C522,1-PARÂMETROS!B5))*SQRT(PARÂMETROS!B9) | E18: =D18*PARÂMETROS!B24 | F18: =AVERAGEIF(RETORNOS_HIST!C4:C522,"<"&PERCENTILE(RETORNOS_HIST!C4:C522,1-PARÂMETROS!B5))*-1*SQRT(PARÂMETROS!B9) | G18: =F18*PARÂMETROS!B24
A21: DISTRIBUIÇÃO DE FREQUÊNCIA DOS RETORNOS (para gráfico)
A22: BUCKET (limite sup.) | B22: CONTAGEM | C22: FREQUÊNCIA (%)
A23: -0.05 | B23: =COUNTIF(RETORNOS_HIST!C4:C522,"<="&A23) | C23: =B23/(=COUNTA(RETORNOS_HIST!C4:C522)-1)
A24: -0.04 | B24: =COUNTIF(RETORNOS_HIST!C4:C522,"<="&A24)-COUNTIF(RETORNOS_HIST!C4:C522,"<="&A23) | C24: =B24/(=COUNTA(RETORNOS_HIST!C4:C522)-1)
A25: -0.03 | B25: =COUNTIF(RETORNOS_HIST!C4:C522,"<="&A25)-COUNTIF(RETORNOS_HIST!C4:C522,"<="&A24) | C25: =B25/(=COUNTA(RETORNOS_HIST!C4:C522)-1)
A26: -0.025 | B26: =COUNTIF(RETORNOS_HIST!C4:C522,"<="&A26)-COUNTIF(RETORNOS_HIST!C4:C522,"<="&A25) | C26: =B26/(=COUNTA(RETORNOS_HIST!C4:C522)-1)
A27: -0.02 | B27: =COUNTIF(RETORNOS_HIST!C4:C522,"<="&A27)-COUNTIF(RETORNOS_HIST!C4:C522,"<="&A26) | C27: =B27/(=COUNTA(RETORNOS_HIST!C4:C522)-1)
A28: -0.015 | B28: =COUNTIF(RETORNOS_HIST!C4:C522,"<="&A28)-COUNTIF(RETORNOS_HIST!C4:C522,"<="&A27) | C28: =B28/(=COUNTA(RETORNOS_HIST!C4:C522)-1)
A29: -0.01 | B29: =COUNTIF(RETORNOS_HIST!C4:C522,"<="&A29)-COUNTIF(RETORNOS_HIST!C4:C522,"<="&A28) | C29: =B29/(=COUNTA(RETORNOS_HIST!C4:C522)-1)
A30: -0.005 | B30: =COUNTIF(RETORNOS_HIST!C4:C522,"<="&A30)-COUNTIF(RETORNOS_HIST!C4:C522,"<="&A29) | C30: =B30/(=COUNTA(RETORNOS_HIST!C4:C522)-1)
A31: 0 | B31: =COUNTIF(RETORNOS_HIST!C4:C522,"<="&A31)-COUNTIF(RETORNOS_HIST!C4:C522,"<="&A30) | C31: =B31/(=COUNTA(RETORNOS_HIST!C4:C522)-1)
A32: 0.005 | B32: =COUNTIF(RETORNOS_HIST!C4:C522,"<="&A32)-COUNTIF(RETORNOS_HIST!C4:C522,"<="&A31) | C32: =B32/(=COUNTA(RETORNOS_HIST!C4:C522)-1)
A33: 0.01 | B33: =COUNTIF(RETORNOS_HIST!C4:C522,"<="&A33)-COUNTIF(RETORNOS_HIST!C4:C522,"<="&A32) | C33: =B33/(=COUNTA(RETORNOS_HIST!C4:C522)-1)
A34: 0.015 | B34: =COUNTIF(RETORNOS_HIST!C4:C522,"<="&A34)-COUNTIF(RETORNOS_HIST!C4:C522,"<="&A33) | C34: =B34/(=COUNTA(RETORNOS_HIST!C4:C522)-1)
A35: 0.02 | B35: =COUNTIF(RETORNOS_HIST!C4:C522,"<="&A35)-COUNTIF(RETORNOS_HIST!C4:C522,"<="&A34) | C35: =B35/(=COUNTA(RETORNOS_HIST!C4:C522)-1)
A36: 0.025 | B36: =COUNTIF(RETORNOS_HIST!C4:C522,"<="&A36)-COUNTIF(RETORNOS_HIST!C4:C522,"<="&A35) | C36: =B36/(=COUNTA(RETORNOS_HIST!C4:C522)-1)
A37: 0.03 | B37: =COUNTIF(RETORNOS_HIST!C4:C522,"<="&A37)-COUNTIF(RETORNOS_HIST!C4:C522,"<="&A36) | C37: =B37/(=COUNTA(RETORNOS_HIST!C4:C522)-1)
A38: 0.04 | B38: =COUNTIF(RETORNOS_HIST!C4:C522,"<="&A38)-COUNTIF(RETORNOS_HIST!C4:C522,"<="&A37) | C38: =B38/(=COUNTA(RETORNOS_HIST!C4:C522)-1)
A39: 0.05 | B39: =COUNTIF(RETORNOS_HIST!C4:C522,"<="&A39)-COUNTIF(RETORNOS_HIST!C4:C522,"<="&A38) | C39: =B39/(=COUNTA(RETORNOS_HIST!C4:C522)-1)

Sheet VaR_PARAMÉTRICO
A1: VaR – MÉTODO PARAMÉTRICO (DELTA-NORMAL)
A2: Metodologia: Assume distribuição Normal para os retornos. VaR = Z(α) × σ × √T × Nocional, onde σ é o desvio padrão histórico dos retornos log e Z(α) é o quantil da distribuição normal padrão. Limitação: subestima o VaR em caudas pesadas (fat tails).
A5: ESTATÍSTICAS DOS RETORNOS
A6: Média Retornos Log (μ) | B6: =AVERAGE(RETORNOS_HIST!C4:C522)
A7: Desv. Padrão Diário (σ_d) | B7: =STDEV(RETORNOS_HIST!C4:C522)
A8: Volatilidade Anualizada | B8: =STDEV(RETORNOS_HIST!C4:C522)*SQRT(PARÂMETROS!B10)
A9: Nº Observações | B9: =COUNTA(RETORNOS_HIST!C4:C522)-1
A11: Z-SCORES (quantis da distribuição normal padrão)
A12: Z 99% (unilateral) | B12: 2.326 | E12: Fonte: tabela normal padrão
A13: Z 97,5% (bilateral) | B13: 1.96 | E13: Basileia – Expected Shortfall
A14: Z 95% (unilateral) | B14: 1.645 | E14: Gestão interna
A15: Z 90% (unilateral) | B15: 1.282 | E15: Análise de sensibilidade
A17: RESULTADOS – VaR PARAMÉTRICO
A18: MÉTRICA | B18: CONF. | C18: HORIZONTE | D18: Z-SCORE | E18: VaR (%) | F18: VaR (R$) | G18: Comparação Hist.
A19: VaR Param. | B19: 99% | C19: 1 dia | D19: =B12 | E19: =B12*B7*SQRT(1) | F19: =E19*PARÂMETROS!B24 | G19: =E19-VaR_HISTÓRICO!D15
A20: VaR Param. | B20: 95% | C20: 1 dia | D20: =B14 | E20: =B14*B7*SQRT(1) | F20: =E20*PARÂMETROS!B24 | G20: =E20-VaR_HISTÓRICO!D16
A21: VaR Param. | B21: 99% | C21: 10 dias | D21: =B12 | E21: =B12*B7*SQRT(10) | F21: =E21*PARÂMETROS!B24 | G21: =E21-VaR_HISTÓRICO!D17
A22: VaR Param. | B22: 95% | C22: 10 dias | D22: =B14 | E22: =B14*B7*SQRT(10) | F22: =E22*PARÂMETROS!B24 | G22: =E22-VaR_HISTÓRICO!D18

Sheet EWMA_VOL
A1: VOLATILIDADE EWMA – RISKMETRICS (λ = 0,94)
A2: DATA | B2: RETORNO LOG | C2: r² (t) | D2: VARIÂNCIA EWMA σ²(t) | E2: VOL EWMA σ(t) | F2: VOL EWMA ANUAL. | G2: VaR 99% 1d (%) | H2: VaR 99% 1d (R$)
A3: 44564 | B3: =RETORNOS_HIST!C3 | C3: =0 | D3: =C3 | E3: =SQRT(D3) | F3: =E3*SQRT(PARÂMETROS!B10) | G3: =VaR_PARAMÉTRICO!B12*E3 | H3: =G3*PARÂMETROS!B24
A4: 44565 | B4: =RETORNOS_HIST!C4 | C4: =B4^2 | D4: =C4 | E4: =SQRT(D4) | F4: =E4*SQRT(PARÂMETROS!B10) | G4: =VaR_PARAMÉTRICO!B12*E4 | H4: =G4*PARÂMETROS!B24
A5: 44566 | B5: =RETORNOS_HIST!C5 | C5: =B5^2 | D5: =PARÂMETROS!B21*D4+(1-PARÂMETROS!B21)*C4 | E5: =SQRT(D5) | F5: =E5*SQRT(PARÂMETROS!B10) | G5: =VaR_PARAMÉTRICO!B12*E5 | H5: =G5*PARÂMETROS!B24
A6: 44567 | B6: =RETORNOS_HIST!C6 | C6: =B6^2 | D6: =PARÂMETROS!B21*D5+(1-PARÂMETROS!B21)*C5 | E6: =SQRT(D6) | F6: =E6*SQRT(PARÂMETROS!B10) | G6: =VaR_PARAMÉTRICO!B12*E6 | H6: =G6*PARÂMETROS!B24
A7: 44568 | B7: =RETORNOS_HIST!C7 | C7: =B7^2 | D7: =PARÂMETROS!B21*D6+(1-PARÂMETROS!B21)*C6 | E7: =SQRT(D7) | F7: =E7*SQRT(PARÂMETROS!B10) | G7: =VaR_PARAMÉTRICO!B12*E7 | H7: =G7*PARÂMETROS!B24
A8: 44571 | B8: =RETORNOS_HIST!C8 | C8: =B8^2 | D8: =PARÂMETROS!B21*D7+(1-PARÂMETROS!B21)*C7 | E8: =SQRT(D8) | F8: =E8*SQRT(PARÂMETROS!B10) | G8: =VaR_PARAMÉTRICO!B12*E8 | H8: =G8*PARÂMETROS!B24
A9: 44572 | B9: =RETORNOS_HIST!C9 | C9: =B9^2 | D9: =PARÂMETROS!B21*D8+(1-PARÂMETROS!B21)*C8 | E9: =SQRT(D9) | F9: =E9*SQRT(PARÂMETROS!B10) | G9: =VaR_PARAMÉTRICO!B12*E9 | H9: =G9*PARÂMETROS!B24
A10: 44573 | B10: =RETORNOS_HIST!C10 | C10: =B10^2 | D10: =PARÂMETROS!B21*D9+(1-PARÂMETROS!B21)*C9 | E10: =SQRT(D10) | F10: =E10*SQRT(PARÂMETROS!B10) | G10: =VaR_PARAMÉTRICO!B12*E10 | H10: =G10*PARÂMETROS!B24
A11: 44574 | B11: =RETORNOS_HIST!C11 | C11: =B11^2 | D11: =PARÂMETROS!B21*D10+(1-PARÂMETROS!B21)*C10 | E11: =SQRT(D11) | F11: =E11*SQRT(PARÂMETROS!B10) | G11: =VaR_PARAMÉTRICO!B12*E11 | H11: =G11*PARÂMETROS!B24
A12: 44575 | B12: =RETORNOS_HIST!C12 | C12: =B12^2 | D12: =PARÂMETROS!B21*D11+(1-PARÂMETROS!B21)*C11 | E12: =SQRT(D12) | F12: =E12*SQRT(PARÂMETROS!B10) | G12: =VaR_PARAMÉTRICO!B12*E12 | H12: =G12*PARÂMETROS!B24
A13: 44578 | B13: =RETORNOS_HIST!C13 | C13: =B13^2 | D13: =PARÂMETROS!B21*D12+(1-PARÂMETROS!B21)*C12 | E13: =SQRT(D13) | F13: =E13*SQRT(PARÂMETROS!B10) | G13: =VaR_PARAMÉTRICO!B12*E13 | H13: =G13*PARÂMETROS!B24
A14: 44579 | B14: =RETORNOS_HIST!C14 | C14: =B14^2 | D14: =PARÂMETROS!B21*D13+(1-PARÂMETROS!B21)*C13 | E14: =SQRT(D14) | F14: =E14*SQRT(PARÂMETROS!B10) | G14: =VaR_PARAMÉTRICO!B12*E14 | H14: =G14*PARÂMETROS!B24
A15: 44580 | B15: =RETORNOS_HIST!C15 | C15: =B15^2 | D15: =PARÂMETROS!B21*D14+(1-PARÂMETROS!B21)*C14 | E15: =SQRT(D15) | F15: =E15*SQRT(PARÂMETROS!B10) | G15: =VaR_PARAMÉTRICO!B12*E15 | H15: =G15*PARÂMETROS!B24
A16: 44581 | B16: =RETORNOS_HIST!C16 | C16: =B16^2 | D16: =PARÂMETROS!B21*D15+(1-PARÂMETROS!B21)*C15 | E16: =SQRT(D16) | F16: =E16*SQRT(PARÂMETROS!B10) | G16: =VaR_PARAMÉTRICO!B12*E16 | H16: =G16*PARÂMETROS!B24
A17: 44582 | B17: =RETORNOS_HIST!C17 | C17: =B17^2 | D17: =PARÂMETROS!B21*D16+(1-PARÂMETROS!B21)*C16 | E17: =SQRT(D17) | F17: =E17*SQRT(PARÂMETROS!B10) | G17: =VaR_PARAMÉTRICO!B12*E17 | H17: =G17*PARÂMETROS!B24
A18: 44585 | B18: =RETORNOS_HIST!C18 | C18: =B18^2 | D18: =PARÂMETROS!B21*D17+(1-PARÂMETROS!B21)*C17 | E18: =SQRT(D18) | F18: =E18*SQRT(PARÂMETROS!B10) | G18: =VaR_PARAMÉTRICO!B12*E18 | H18: =G18*PARÂMETROS!B24
A19: 44586 | B19: =RETORNOS_HIST!C19 | C19: =B19^2 | D19: =PARÂMETROS!B21*D18+(1-PARÂMETROS!B21)*C18 | E19: =SQRT(D19) | F19: =E19*SQRT(PARÂMETROS!B10) | G19: =VaR_PARAMÉTRICO!B12*E19 | H19: =G19*PARÂMETROS!B24
A20: 44587 | B20: =RETORNOS_HIST!C20 | C20: =B20^2 | D20: =PARÂMETROS!B21*D19+(1-PARÂMETROS!B21)*C19 | E20: =SQRT(D20) | F20: =E20*SQRT(PARÂMETROS!B10) | G20: =VaR_PARAMÉTRICO!B12*E20 | H20: =G20*PARÂMETROS!B24
A21: 44588 | B21: =RETORNOS_HIST!C21 | C21: =B21^2 | D21: =PARÂMETROS!B21*D20+(1-PARÂMETROS!B21)*C20 | E21: =SQRT(D21) | F21: =E21*SQRT(PARÂMETROS!B10) | G21: =VaR_PARAMÉTRICO!B12*E21 | H21: =G21*PARÂMETROS!B24
A22: 44589 | B22: =RETORNOS_HIST!C22 | C22: =B22^2 | D22: =PARÂMETROS!B21*D21+(1-PARÂMETROS!B21)*C21 | E22: =SQRT(D22) | F22: =E22*SQRT(PARÂMETROS!B10) | G22: =VaR_PARAMÉTRICO!B12*E22 | H22: =G22*PARÂMETROS!B24
A23: 44592 | B23: =RETORNOS_HIST!C23 | C23: =B23^2 | D23: =PARÂMETROS!B21*D22+(1-PARÂMETROS!B21)*C22 | E23: =SQRT(D23) | F23: =E23*SQRT(PARÂMETROS!B10) | G23: =VaR_PARAMÉTRICO!B12*E23 | H23: =G23*PARÂMETROS!B24
A24: 44593 | B24: =RETORNOS_HIST!C24 | C24: =B24^2 | D24: =PARÂMETROS!B21*D23+(1-PARÂMETROS!B21)*C23 | E24: =SQRT(D24) | F24: =E24*SQRT(PARÂMETROS!B10) | G24: =VaR_PARAMÉTRICO!B12*E24 | H24: =G24*PARÂMETROS!B24
A25: 44594 | B25: =RETORNOS_HIST!C25 | C25: =B25^2 | D25: =PARÂMETROS!B21*D24+(1-PARÂMETROS!B21)*C24 | E25: =SQRT(D25) | F25: =E25*SQRT(PARÂMETROS!B10) | G25: =VaR_PARAMÉTRICO!B12*E25 | H25: =G25*PARÂMETROS!B24
A26: 44595 | B26: =RETORNOS_HIST!C26 | C26: =B26^2 | D26: =PARÂMETROS!B21*D25+(1-PARÂMETROS!B21)*C25 | E26: =SQRT(D26) | F26: =E26*SQRT(PARÂMETROS!B10) | G26: =VaR_PARAMÉTRICO!B12*E26 | H26: =G26*PARÂMETROS!B24
A27: 44596 | B27: =RETORNOS_HIST!C27 | C27: =B27^2 | D27: =PARÂMETROS!B21*D26+(1-PARÂMETROS!B21)*C26 | E27: =SQRT(D27) | F27: =E27*SQRT(PARÂMETROS!B10) | G27: =VaR_PARAMÉTRICO!B12*E27 | H27: =G27*PARÂMETROS!B24
A28: 44599 | B28: =RETORNOS_HIST!C28 | C28: =B28^2 | D28: =PARÂMETROS!B21*D27+(1-PARÂMETROS!B21)*C27 | E28: =SQRT(D28) | F28: =E28*SQRT(PARÂMETROS!B10) | G28: =VaR_PARAMÉTRICO!B12*E28 | H28: =G28*PARÂMETROS!B24
A29: 44600 | B29: =RETORNOS_HIST!C29 | C29: =B29^2 | D29: =PARÂMETROS!B21*D28+(1-PARÂMETROS!B21)*C28 | E29: =SQRT(D29) | F29: =E29*SQRT(PARÂMETROS!B10) | G29: =VaR_PARAMÉTRICO!B12*E29 | H29: =G29*PARÂMETROS!B24
A30: 44601 | B30: =RETORNOS_HIST!C30 | C30: =B30^2 | D30: =PARÂMETROS!B21*D29+(1-PARÂMETROS!B21)*C29 | E30: =SQRT(D30) | F30: =E30*SQRT(PARÂMETROS!B10) | G30: =VaR_PARAMÉTRICO!B12*E30 | H30: =G30*PARÂMETROS!B24
A31: 44602 | B31: =RETORNOS_HIST!C31 | C31: =B31^2 | D31: =PARÂMETROS!B21*D30+(1-PARÂMETROS!B21)*C30 | E31: =SQRT(D31) | F31: =E31*SQRT(PARÂMETROS!B10) | G31: =VaR_PARAMÉTRICO!B12*E31 | H31: =G31*PARÂMETROS!B24
A32: 44603 | B32: =RETORNOS_HIST!C32 | C32: =B32^2 | D32: =PARÂMETROS!B21*D31+(1-PARÂMETROS!B21)*C31 | E32: =SQRT(D32) | F32: =E32*SQRT(PARÂMETROS!B10) | G32: =VaR_PARAMÉTRICO!B12*E32 | H32: =G32*PARÂMETROS!B24
A33: 44606 | B33: =RETORNOS_HIST!C33 | C33: =B33^2 | D33: =PARÂMETROS!B21*D32+(1-PARÂMETROS!B21)*C32 | E33: =SQRT(D33) | F33: =E33*SQRT(PARÂMETROS!B10) | G33: =VaR_PARAMÉTRICO!B12*E33 | H33: =G33*PARÂMETROS!B24
A34: 44607 | B34: =RETORNOS_HIST!C34 | C34: =B34^2 | D34: =PARÂMETROS!B21*D33+(1-PARÂMETROS!B21)*C33 | E34: =SQRT(D34) | F34: =E34*SQRT(PARÂMETROS!B10) | G34: =VaR_PARAMÉTRICO!B12*E34 | H34: =G34*PARÂMETROS!B24
A35: 44608 | B35: =RETORNOS_HIST!C35 | C35: =B35^2 | D35: =PARÂMETROS!B21*D34+(1-PARÂMETROS!B21)*C34 | E35: =SQRT(D35) | F35: =E35*SQRT(PARÂMETROS!B10) | G35: =VaR_PARAMÉTRICO!B12*E35 | H35: =G35*PARÂMETROS!B24
A36: 44609 | B36: =RETORNOS_HIST!C36 | C36: =B36^2 | D36: =PARÂMETROS!B21*D35+(1-PARÂMETROS!B21)*C35 | E36: =SQRT(D36) | F36: =E36*SQRT(PARÂMETROS!B10) | G36: =VaR_PARAMÉTRICO!B12*E36 | H36: =G36*PARÂMETROS!B24
A37: 44610 | B37: =RETORNOS_HIST!C37 | C37: =B37^2 | D37: =PARÂMETROS!B21*D36+(1-PARÂMETROS!B21)*C36 | E37: =SQRT(D37) | F37: =E37*SQRT(PARÂMETROS!B10) | G37: =VaR_PARAMÉTRICO!B12*E37 | H37: =G37*PARÂMETROS!B24
A38: 44613 | B38: =RETORNOS_HIST!C38 | C38: =B38^2 | D38: =PARÂMETROS!B21*D37+(1-PARÂMETROS!B21)*C37 | E38: =SQRT(D38) | F38: =E38*SQRT(PARÂMETROS!B10) | G38: =VaR_PARAMÉTRICO!B12*E38 | H38: =G38*PARÂMETROS!B24
A39: 44614 | B39: =RETORNOS_HIST!C39 | C39: =B39^2 | D39: =PARÂMETROS!B21*D38+(1-PARÂMETROS!B21)*C38 | E39: =SQRT(D39) | F39: =E39*SQRT(PARÂMETROS!B10) | G39: =VaR_PARAMÉTRICO!B12*E39 | H39: =G39*PARÂMETROS!B24
A40: 44615 | B40: =RETORNOS_HIST!C40 | C40: =B40^2 | D40: =PARÂMETROS!B21*D39+(1-PARÂMETROS!B21)*C39 | E40: =SQRT(D40) | F40: =E40*SQRT(PARÂMETROS!B10) | G40: =VaR_PARAMÉTRICO!B12*E40 | H40: =G40*PARÂMETROS!B24
...

Sheet BACKTESTING
A1: BACKTESTING – SEMÁFORO DE BASILEIA
A2: DATA | B2: RETORNO REAL (%) | C2: VaR 99% 1d (%) | D2: EXCEÇÃO? | E2: Nº ORDEM EXCEÇÃO | F2: OBSERVAÇÃO
A3: 44942 | B3: =RETORNOS_HIST!C274 | C3: =VaR_PARAMÉTRICO!E19 | D3: =IF(B3<-C3,"SIM","NÃO") | E3: =IF(D3="SIM",1,0)
A4: 44943 | B4: =RETORNOS_HIST!C275 | C4: =VaR_PARAMÉTRICO!E19 | D4: =IF(B4<-C4,"SIM","NÃO") | E4: =IF(D4="SIM",E3+1,E3)
A5: 44944 | B5: =RETORNOS_HIST!C276 | C5: =VaR_PARAMÉTRICO!E19 | D5: =IF(B5<-C5,"SIM","NÃO") | E5: =IF(D5="SIM",E4+1,E4)
A6: 44945 | B6: =RETORNOS_HIST!C277 | C6: =VaR_PARAMÉTRICO!E19 | D6: =IF(B6<-C6,"SIM","NÃO") | E6: =IF(D6="SIM",E5+1,E5)
A7: 44946 | B7: =RETORNOS_HIST!C278 | C7: =VaR_PARAMÉTRICO!E19 | D7: =IF(B7<-C7,"SIM","NÃO") | E7: =IF(D7="SIM",E6+1,E6)
A8: 44949 | B8: =RETORNOS_HIST!C279 | C8: =VaR_PARAMÉTRICO!E19 | D8: =IF(B8<-C8,"SIM","NÃO") | E8: =IF(D8="SIM",E7+1,E7)
A9: 44950 | B9: =RETORNOS_HIST!C280 | C9: =VaR_PARAMÉTRICO!E19 | D9: =IF(B9<-C9,"SIM","NÃO") | E9: =IF(D9="SIM",E8+1,E8)
A10: 44951 | B10: =RETORNOS_HIST!C281 | C10: =VaR_PARAMÉTRICO!E19 | D10: =IF(B10<-C10,"SIM","NÃO") | E10: =IF(D10="SIM",E9+1,E9)
A11: 44952 | B11: =RETORNOS_HIST!C282 | C11: =VaR_PARAMÉTRICO!E19 | D11: =IF(B11<-C11,"SIM","NÃO") | E11: =IF(D11="SIM",E10+1,E10)
A12: 44953 | B12: =RETORNOS_HIST!C283 | C12: =VaR_PARAMÉTRICO!E19 | D12: =IF(B12<-C12,"SIM","NÃO") | E12: =IF(D12="SIM",E11+1,E11)
A13: 44956 | B13: =RETORNOS_HIST!C284 | C13: =VaR_PARAMÉTRICO!E19 | D13: =IF(B13<-C13,"SIM","NÃO") | E13: =IF(D13="SIM",E12+1,E12)
A14: 44957 | B14: =RETORNOS_HIST!C285 | C14: =VaR_PARAMÉTRICO!E19 | D14: =IF(B14<-C14,"SIM","NÃO") | E14: =IF(D14="SIM",E13+1,E13)
A15: 44958 | B15: =RETORNOS_HIST!C286 | C15: =VaR_PARAMÉTRICO!E19 | D15: =IF(B15<-C15,"SIM","NÃO") | E15: =IF(D15="SIM",E14+1,E14)
A16: 44959 | B16: =RETORNOS_HIST!C287 | C16: =VaR_PARAMÉTRICO!E19 | D16: =IF(B16<-C16,"SIM","NÃO") | E16: =IF(D16="SIM",E15+1,E15)
A17: 44960 | B17: =RETORNOS_HIST!C288 | C17: =VaR_PARAMÉTRICO!E19 | D17: =IF(B17<-C17,"SIM","NÃO") | E17: =IF(D17="SIM",E16+1,E16)
A18: 44963 | B18: =RETORNOS_HIST!C289 | C18: =VaR_PARAMÉTRICO!E19 | D18: =IF(B18<-C18,"SIM","NÃO") | E18: =IF(D18="SIM",E17+1,E17)
A19: 44964 | B19: =RETORNOS_HIST!C290 | C19: =VaR_PARAMÉTRICO!E19 | D19: =IF(B19<-C19,"SIM","NÃO") | E19: =IF(D19="SIM",E18+1,E18)
A20: 44965 | B20: =RETORNOS_HIST!C291 | C20: =VaR_PARAMÉTRICO!E19 | D20: =IF(B20<-C20,"SIM","NÃO") | E20: =IF(D20="SIM",E19+1,E19)
A21: 44966 | B21: =RETORNOS_HIST!C292 | C21: =VaR_PARAMÉTRICO!E19 | D21: =IF(B21<-C21,"SIM","NÃO") | E21: =IF(D21="SIM",E20+1,E20)
A22: 44967 | B22: =RETORNOS_HIST!C293 | C22: =VaR_PARAMÉTRICO!E19 | D22: =IF(B22<-C22,"SIM","NÃO") | E22: =IF(D22="SIM",E21+1,E21)
A23: 44970 | B23: =RETORNOS_HIST!C294 | C23: =VaR_PARAMÉTRICO!E19 | D23: =IF(B23<-C23,"SIM","NÃO") | E23: =IF(D23="SIM",E22+1,E22)
A24: 44971 | B24: =RETORNOS_HIST!C295 | C24: =VaR_PARAMÉTRICO!E19 | D24: =IF(B24<-C24,"SIM","NÃO") | E24: =IF(D24="SIM",E23+1,E23)
A25: 44972 | B25: =RETORNOS_HIST!C296 | C25: =VaR_PARAMÉTRICO!E19 | D25: =IF(B25<-C25,"SIM","NÃO") | E25: =IF(D25="SIM",E24+1,E24)
A26: 44973 | B26: =RETORNOS_HIST!C297 | C26: =VaR_PARAMÉTRICO!E19 | D26: =IF(B26<-C26,"SIM","NÃO") | E26: =IF(D26="SIM",E25+1,E25)
A27: 44974 | B27: =RETORNOS_HIST!C298 | C27: =VaR_PARAMÉTRICO!E19 | D27: =IF(B27<-C27,"SIM","NÃO") | E27: =IF(D27="SIM",E26+1,E26)
A28: 44977 | B28: =RETORNOS_HIST!C299 | C28: =VaR_PARAMÉTRICO!E19 | D28: =IF(B28<-C28,"SIM","NÃO") | E28: =IF(D28="SIM",E27+1,E27)
A29: 44978 | B29: =RETORNOS_HIST!C300 | C29: =VaR_PARAMÉTRICO!E19 | D29: =IF(B29<-C29,"SIM","NÃO") | E29: =IF(D29="SIM",E28+1,E28)
A30: 44979 | B30: =RETORNOS_HIST!C301 | C30: =VaR_PARAMÉTRICO!E19 | D30: =IF(B30<-C30,"SIM","NÃO") | E30: =IF(D30="SIM",E29+1,E29)
A31: 44980 | B31: =RETORNOS_HIST!C302 | C31: =VaR_PARAMÉTRICO!E19 | D31: =IF(B31<-C31,"SIM","NÃO") | E31: =IF(D31="SIM",E30+1,E30)
A32: 44981 | B32: =RETORNOS_HIST!C303 | C32: =VaR_PARAMÉTRICO!E19 | D32: =IF(B32<-C32,"SIM","NÃO") | E32: =IF(D32="SIM",E31+1,E31)
A33: 44984 | B33: =RETORNOS_HIST!C304 | C33: =VaR_PARAMÉTRICO!E19 | D33: =IF(B33<-C33,"SIM","NÃO") | E33: =IF(D33="SIM",E32+1,E32)
A34: 44985 | B34: =RETORNOS_HIST!C305 | C34: =VaR_PARAMÉTRICO!E19 | D34: =IF(B34<-C34,"SIM","NÃO") | E34: =IF(D34="SIM",E33+1,E33)
A35: 44986 | B35: =RETORNOS_HIST!C306 | C35: =VaR_PARAMÉTRICO!E19 | D35: =IF(B35<-C35,"SIM","NÃO") | E35: =IF(D35="SIM",E34+1,E34)
A36: 44987 | B36: =RETORNOS_HIST!C307 | C36: =VaR_PARAMÉTRICO!E19 | D36: =IF(B36<-C36,"SIM","NÃO") | E36: =IF(D36="SIM",E35+1,E35)
A37: 44988 | B37: =RETORNOS_HIST!C308 | C37: =VaR_PARAMÉTRICO!E19 | D37: =IF(B37<-C37,"SIM","NÃO") | E37: =IF(D37="SIM",E36+1,E36)
A38: 44991 | B38: =RETORNOS_HIST!C309 | C38: =VaR_PARAMÉTRICO!E19 | D38: =IF(B38<-C38,"SIM","NÃO") | E38: =IF(D38="SIM",E37+1,E37)
A39: 44992 | B39: =RETORNOS_HIST!C310 | C39: =VaR_PARAMÉTRICO!E19 | D39: =IF(B39<-C39,"SIM","NÃO") | E39: =IF(D39="SIM",E38+1,E38)
A40: 44993 | B40: =RETORNOS_HIST!C311 | C40: =VaR_PARAMÉTRICO!E19 | D40: =IF(B40<-C40,"SIM","NÃO") | E40: =IF(D40="SIM",E39+1,E39)
...

Sheet STRESS_TEST
A1: TESTES DE ESTRESSE – CENÁRIOS HISTÓRICOS E HIPOTÉTICOS
A2: 1. CENÁRIOS HISTÓRICOS
A3: EVENTO | B3: PERÍODO | C3: QUEDA MÁX. IBOV (%) | D3: PIOR DIA (%) | E3: DURAÇÃO (dias) | F3: IBOV INICIAL | G3: IBOV MÍN. | H3: IMPACTO (R$)
A4: Crise Subprime 2008 | B4: Set/2008 – Mar/2009 | C4: -0.602 | D4: -0.124 | E4: 180 | F4: 73920 | G4: 29435 | H4: =C4*PARÂMETROS!B24
A5: Crise Europeia 2011 | B5: Jul/2011 – Ago/2011 | C5: -0.272 | D5: -0.068 | E5: 45 | F5: 65000 | G5: 47318 | H5: =C5*PARÂMETROS!B24
A6: Crise Política Brasil 2015 | B6: Jan/2015 – Set/2015 | C6: -0.341 | D6: -0.051 | E6: 180 | F6: 51000 | G6: 37046 | H6: =C6*PARÂMETROS!B24
A7: COVID-19 Crash Mar/2020 | B7: Fev/2020 – Mar/2020 | C7: -0.466 | D7: -0.145 | E7: 30 | F7: 119527 | G7: 63570 | H7: =C7*PARÂMETROS!B24
A8: Crise Americanas Jan/2023 | B8: Jan/2023 | C8: -0.038 | D8: -0.031 | E8: 5 | F8: 109000 | G8: 104823 | H8: =C8*PARÂMETROS!B24
A9: Eleições Out/2022 | B9: Out/2022 | C9: -0.052 | D9: -0.041 | E9: 10 | F9: 116000 | G9: 109965 | H9: =C9*PARÂMETROS!B24
A11: 2. CENÁRIOS HIPOTÉTICOS (choque instantâneo no Ibovespa)
A12: CENÁRIO | B12: QUEDA HIPOTÉTICA (%) | C12: IMPACTO (R$) | D12: VaR DIÁRIO EQUIV. (%) | E12: MÚLTIPLO DO VaR 99% | F12: PROBABILIDADE NORMAL | G12: CLASSIFICAÇÃO
A13: Queda de 5% | B13: -0.05 | C13: =B13*PARÂMETROS!B24 | D13: =ABS(B13) | E13: =ABS(B13)/VaR_PARAMÉTRICO!E19 | F13: =NORM.DIST(B13/VaR_PARAMÉTRICO!B7,0,1,TRUE) | G13: =IF(ABS(B13)>VaR_PARAMÉTRICO!E19*3,"EXTREMO",IF(ABS(B13)>VaR_PARAMÉTRICO!E19,"SEVERO","MODERADO"))
A14: Queda de 10% | B14: -0.1 | C14: =B14*PARÂMETROS!B24 | D14: =ABS(B14) | E14: =ABS(B14)/VaR_PARAMÉTRICO!E19 | F14: =NORM.DIST(B14/VaR_PARAMÉTRICO!B7,0,1,TRUE) | G14: =IF(ABS(B14)>VaR_PARAMÉTRICO!E19*3,"EXTREMO",IF(ABS(B14)>VaR_PARAMÉTRICO!E19,"SEVERO","MODERADO"))
A15: Queda de 15% | B15: -0.15 | C15: =B15*PARÂMETROS!B24 | D15: =ABS(B15) | E15: =ABS(B15)/VaR_PARAMÉTRICO!E19 | F15: =NORM.DIST(B15/VaR_PARAMÉTRICO!B7,0,1,TRUE) | G15: =IF(ABS(B15)>VaR_PARAMÉTRICO!E19*3,"EXTREMO",IF(ABS(B15)>VaR_PARAMÉTRICO!E19,"SEVERO","MODERADO"))
A16: Queda de 20% | B16: -0.2 | C16: =B16*PARÂMETROS!B24 | D16: =ABS(B16) | E16: =ABS(B16)/VaR_PARAMÉTRICO!E19 | F16: =NORM.DIST(B16/VaR_PARAMÉTRICO!B7,0,1,TRUE) | G16: =IF(ABS(B16)>VaR_PARAMÉTRICO!E19*3,"EXTREMO",IF(ABS(B16)>VaR_PARAMÉTRICO!E19,"SEVERO","MODERADO"))
A17: Queda de 25% | B17: -0.25 | C17: =B17*PARÂMETROS!B24 | D17: =ABS(B17) | E17: =ABS(B17)/VaR_PARAMÉTRICO!E19 | F17: =NORM.DIST(B17/VaR_PARAMÉTRICO!B7,0,1,TRUE) | G17: =IF(ABS(B17)>VaR_PARAMÉTRICO!E19*3,"EXTREMO",IF(ABS(B17)>VaR_PARAMÉTRICO!E19,"SEVERO","MODERADO"))
A18: Queda de 30% | B18: -0.3 | C18: =B18*PARÂMETROS!B24 | D18: =ABS(B18) | E18: =ABS(B18)/VaR_PARAMÉTRICO!E19 | F18: =NORM.DIST(B18/VaR_PARAMÉTRICO!B7,0,1,TRUE) | G18: =IF(ABS(B18)>VaR_PARAMÉTRICO!E19*3,"EXTREMO",IF(ABS(B18)>VaR_PARAMÉTRICO!E19,"SEVERO","MODERADO"))
A19: Queda de 40% | B19: -0.4 | C19: =B19*PARÂMETROS!B24 | D19: =ABS(B19) | E19: =ABS(B19)/VaR_PARAMÉTRICO!E19 | F19: =NORM.DIST(B19/VaR_PARAMÉTRICO!B7,0,1,TRUE) | G19: =IF(ABS(B19)>VaR_PARAMÉTRICO!E19*3,"EXTREMO",IF(ABS(B19)>VaR_PARAMÉTRICO!E19,"SEVERO","MODERADO"))
A20: Queda de 50% | B20: -0.5 | C20: =B20*PARÂMETROS!B24 | D20: =ABS(B20) | E20: =ABS(B20)/VaR_PARAMÉTRICO!E19 | F20: =NORM.DIST(B20/VaR_PARAMÉTRICO!B7,0,1,TRUE) | G20: =IF(ABS(B20)>VaR_PARAMÉTRICO!E19*3,"EXTREMO",IF(ABS(B20)>VaR_PARAMÉTRICO!E19,"SEVERO","MODERADO"))
A22: 3. SENSIBILIDADE DO VaR POR NÍVEL DE CONFIANÇA
A23: NÍVEL CONFIANÇA | B23: Z-SCORE | C23: VaR PARAM. (%) | D23: VaR PARAM. (R$) | E23: VaR HIST. (%)
A24: 0.9 | B24: 1.282 | C24: =B24*VaR_PARAMÉTRICO!B7 | D24: =C24*PARÂMETROS!B24 | E24: =ABS(PERCENTILE(RETORNOS_HIST!C4:C522,1-A24))
A25: 0.95 | B25: 1.645 | C25: =B25*VaR_PARAMÉTRICO!B7 | D25: =C25*PARÂMETROS!B24 | E25: =ABS(PERCENTILE(RETORNOS_HIST!C4:C522,1-A25))
A26: 0.975 | B26: 1.96 | C26: =B26*VaR_PARAMÉTRICO!B7 | D26: =C26*PARÂMETROS!B24 | E26: =ABS(PERCENTILE(RETORNOS_HIST!C4:C522,1-A26))
A27: 0.99 | B27: 2.326 | C27: =B27*VaR_PARAMÉTRICO!B7 | D27: =C27*PARÂMETROS!B24 | E27: =ABS(PERCENTILE(RETORNOS_HIST!C4:C522,1-A27))
A28: 0.995 | B28: 2.576 | C28: =B28*VaR_PARAMÉTRICO!B7 | D28: =C28*PARÂMETROS!B24 | E28: =ABS(PERCENTILE(RETORNOS_HIST!C4:C522,1-A28))
A29: 0.999 | B29: 3.09 | C29: =B29*VaR_PARAMÉTRICO!B7 | D29: =C29*PARÂMETROS!B24 | E29: =ABS(PERCENTILE(RETORNOS_HIST!C4:C522,1-A29))

Sheet MONTE_CARLO
A1: SIMULAÇÃO MONTE CARLO – 1 000 CENÁRIOS (VALORES FIXOS)
A2: Metodologia: Gera N cenários de retorno diário assumindo distribuição Normal: r_i = μ + σ × Z_i, onde Z_i ~ N(0,1). μ e σ são estimados a partir da janela histórica. Os valores abaixo são FIXOS (semente aleatória = 42) para reprodutibilidade do modelo. O VaR é estimado como o percentil (1-α) dos cenários simulados. Para re-simulação, alterar a semente nos parâmetros.
A5: PARÂMETROS DA SIMULAÇÃO
A6: μ (média histórica) | B6: =AVERAGE(RETORNOS_HIST!C4:C522)
A7: σ (desvio padrão histórico) | B7: =STDEV(RETORNOS_HIST!C4:C522)
A8: N simulações | B8: 1000
A9: Horizonte | B9: 1
A10: Semente aleatória | B10: 42
A11: Nocional | B11: =PARÂMETROS!B24
A13: CENÁRIOS SIMULADOS (primeiros 500 exibidos; todos 1 000 usados nos cálculos) | I13: DISTRIBUIÇÃO DE FREQUÊNCIA
A14: CENÁRIO # | B14: RETORNO SIMULADO (%) | C14: RETORNO ACUMULADO 1d | D14: P&L SIMULADO (R$) | I14: BUCKET | J14: COUNT | K14: FREQ (%)
A15: 1 | B15: -0.00157908 | C15: =EXP(B15)-1 | D15: =B15*$B$11 | I15: -0.05 | J15: =COUNTIF($B$15:$B$1014,"<="&I15) | K15: =J15/B$8
A16: 2 | B16: -0.00192484 | C16: =EXP(B16)-1 | D16: =B16*$B$11 | I16: -0.04 | J16: =COUNTIF($B$15:$B$1014,"<="&I16)-COUNTIF($B$15:$B$1014,"<="&I15) | K16: =J16/B$8
A17: 3 | B17: -0.00118579 | C17: =EXP(B17)-1 | D17: =B17*$B$11 | I17: -0.03 | J17: =COUNTIF($B$15:$B$1014,"<="&I17)-COUNTIF($B$15:$B$1014,"<="&I16) | K17: =J17/B$8
A18: 4 | B18: 0.0085738 | C18: =EXP(B18)-1 | D18: =B18*$B$11 | I18: -0.025 | J18: =COUNTIF($B$15:$B$1014,"<="&I18)-COUNTIF($B$15:$B$1014,"<="&I17) | K18: =J18/B$8
A19: 5 | B19: -0.00138106 | C19: =EXP(B19)-1 | D19: =B19*$B$11 | I19: -0.02 | J19: =COUNTIF($B$15:$B$1014,"<="&I19)-COUNTIF($B$15:$B$1014,"<="&I18) | K19: =J19/B$8
A20: 6 | B20: -0.01781824 | C20: =EXP(B20)-1 | D20: =B20*$B$11 | I20: -0.015 | J20: =COUNTIF($B$15:$B$1014,"<="&I20)-COUNTIF($B$15:$B$1014,"<="&I19) | K20: =J20/B$8
A21: 7 | B21: 0.00413782 | C21: =EXP(B21)-1 | D21: =B21*$B$11 | I21: -0.01 | J21: =COUNTIF($B$15:$B$1014,"<="&I21)-COUNTIF($B$15:$B$1014,"<="&I20) | K21: =J21/B$8
A22: 8 | B22: -0.00305805 | C22: =EXP(B22)-1 | D22: =B22*$B$11 | I22: -0.005 | J22: =COUNTIF($B$15:$B$1014,"<="&I22)-COUNTIF($B$15:$B$1014,"<="&I21) | K22: =J22/B$8
A23: 9 | B23: -0.0024535 | C23: =EXP(B23)-1 | D23: =B23*$B$11 | I23: 0 | J23: =COUNTIF($B$15:$B$1014,"<="&I23)-COUNTIF($B$15:$B$1014,"<="&I22) | K23: =J23/B$8
A24: 10 | B24: 0.00154062 | C24: =EXP(B24)-1 | D24: =B24*$B$11 | I24: 0.005 | J24: =COUNTIF($B$15:$B$1014,"<="&I24)-COUNTIF($B$15:$B$1014,"<="&I23) | K24: =J24/B$8
A25: 11 | B25: 0.00293757 | C25: =EXP(B25)-1 | D25: =B25*$B$11 | I25: 0.01 | J25: =COUNTIF($B$15:$B$1014,"<="&I25)-COUNTIF($B$15:$B$1014,"<="&I24) | K25: =J25/B$8
A26: 12 | B26: 0.0141127 | C26: =EXP(B26)-1 | D26: =B26*$B$11 | I26: 0.015 | J26: =COUNTIF($B$15:$B$1014,"<="&I26)-COUNTIF($B$15:$B$1014,"<="&I25) | K26: =J26/B$8
A27: 13 | B27: 0.00802964 | C27: =EXP(B27)-1 | D27: =B27*$B$11 | I27: 0.02 | J27: =COUNTIF($B$15:$B$1014,"<="&I27)-COUNTIF($B$15:$B$1014,"<="&I26) | K27: =J27/B$8
... A31: 17 | B31: 0.00310611 | C31: =EXP(B31)-1 | D31: =B31*$B$11 | I31: 0.05 | J31: =COUNTIF($B$15:$B$1014,"<="&I31)-COUNTIF($B$15:$B$1014,"<="&I30) | K31: =J31/B$8
A32: 18 | B32: 0.01588297 | C32: =EXP(B32)-1 | D32: =B32*$B$11
A33: 19 | B33: 0.00064988 | C33: =EXP(B33)-1 | D33: =B33*$B$11
A34: 20 | B34: -0.00112588 | C34: =EXP(B34)-1 | D34: =B34*$B$11
A35: 21 | B35: 0.00653131 | C35: =EXP(B35)-1 | D35: =B35*$B$11
A36: 22 | B36: -0.01729254 | C36: =EXP(B36)-1 | D36: =B36*$B$11
A37: 23 | B37: -0.00359733 | C37: =EXP(B37)-1 | D37: =B37*$B$11
A38: 24 | B38: 0.00603435 | C38: =EXP(B38)-1 | D38: =B38*$B$11
A39: 25 | B39: 0.01063085 | C39: =EXP(B39)-1 | D39: =B39*$B$11
A40: 26 | B40: -0.00273756 | C40: =EXP(B40)-1 | D40: =B40*$B$11
A41: 27 | B41: 0.0046692 | C41: =EXP(B41)-1 | D41: =B41*$B$11
A42: 28 | B42: 0.00312856 | C42: =EXP(B42)-1 | D42: =B42*$B$11
A43: 29 | B43: 0.00953792 | C43: =EXP(B43)-1 | D43: =B43*$B$11
... A1014: 1000 | B1014: -0.00706492 | C1014: =EXP(B1014)-1 | D1014: =B1014*$B$11
A1016: RESULTADOS – VaR MONTE CARLO
A1017: VaR 99% 1d (%) | B1017: =ABS(PERCENTILE(B15:B1014,0.01))
...

Sheet RESUMO_EXEC
A1: DASHBOARD EXECUTIVO – RESUMO DE RISCO DE MERCADO
A2: Ibovespa | Risco de Mercado – Tesouraria | Confidencial
A3: INFORMAÇÕES DA POSIÇÃO
A4: Data de Referência | B4: =TEXTO(HOJE(),"DD/MM/AAAA")
A5: Ativo | B5: Ibovespa (IBOV)
A6: Nocional (R$) | B6: =PARÂMETROS!B24
A7: Moeda | B7: =PARÂMETROS!B25
A8: Índice Inicial (jan/22) | B8: =RETORNOS_HIST!B3
A9: Índice Atual (dez/23) | B9: =RETORNOS_HIST!B522
A10: Retorno Total Período | B10: =RETORNOS_HIST!B522/RETORNOS_HIST!B3-1
A12: TABELA MESTRE DE VaR – CONSOLIDAÇÃO DOS MÉTODOS
A13: MÉTODO | B13: HORIZONTE | C13: CONF. 95%(%) | D13: CONF. 95%(R$) | E13: CONF. 99%(%) | F13: CONF. 99%(R$) | G13: CVaR 99%(%) | H13: CVaR 99%(R$)
A14: Histórico | B14: 1 dia | C14: =VaR_HISTÓRICO!D16 | D14: =VaR_HISTÓRICO!E16 | E14: =VaR_HISTÓRICO!D15 | F14: =VaR_HISTÓRICO!E15 | G14: =VaR_HISTÓRICO!F15 | H14: =VaR_HISTÓRICO!G15
A15: Histórico | B15: 10 dias | C15: =VaR_HISTÓRICO!D18 | D15: =VaR_HISTÓRICO!E18 | E15: =VaR_HISTÓRICO!D17 | F15: =VaR_HISTÓRICO!E17 | G15: =VaR_HISTÓRICO!F17 | H15: =VaR_HISTÓRICO!G17
A16: Paramétrico | B16: 1 dia | C16: =VaR_PARAMÉTRICO!E20 | D16: =VaR_PARAMÉTRICO!F20 | E16: =VaR_PARAMÉTRICO!E19 | F16: =VaR_PARAMÉTRICO!F19 | G16: =VaR_PARAMÉTRICO!E19*1.25 | H16: =VaR_PARAMÉTRICO!F19*1.25
A17: Paramétrico | B17: 10 dias | C17: =VaR_PARAMÉTRICO!E22 | D17: =VaR_PARAMÉTRICO!F22 | E17: =VaR_PARAMÉTRICO!E21 | F17: =VaR_PARAMÉTRICO!F21 | G17: =VaR_PARAMÉTRICO!E21*1.25 | H17: =VaR_PARAMÉTRICO!F21*1.25
A18: EWMA | B18: 1 dia | C18: =EWMA_VOL!G522*VaR_PARAMÉTRICO!B14/VaR_PARAMÉTRICO!B12 | D18: =EWMA_VOL!H522*VaR_PARAMÉTRICO!B14/VaR_PARAMÉTRICO!B12 | E18: =EWMA_VOL!G522 | F18: =EWMA_VOL!H522 | G18: =EWMA_VOL!G522*1.25 | H18: =EWMA_VOL!H522*1.25
A19: Monte Carlo | B19: 1 dia | C19: =MONTE_CARLO!B1019 | D19: =MONTE_CARLO!B1020 | E19: =MONTE_CARLO!B1017 | F19: =MONTE_CARLO!B1018 | G19: =MONTE_CARLO!B1021 | H19: =MONTE_CARLO!B1022
A21: ALERTAS E SEMÁFOROS
A22: Backtesting | B22: =BACKTESTING!C265
A23: Maior VaR 99% 1d | B23: =MAX(E14:E19)
A24: VaR/Nocional > 5%? | B24: =IF(MAX(E14:E19)>0.05,"⚠ ATENÇÃO – EXCEDE LIMITE","✓ DENTRO DO LIMITE")
A25: Nº Exceções BT | B25: =COUNTIF(BACKTESTING!D3:D252,"SIM")
A28: Modelo aprovado pela Diretoria de Risco | Versão 2.1 | Uso interno e confidencial | © 2026 Banco Modelo S.A.
